Workbook
Name JR_PAGE_ANCHOR_0_1: CT!$A$1

Sheet BaoCao202510
A1: ID | B1: Tháng | C1: Tên HV | D1: Mã HV | E1: Lớp TT | F1: Môn Toán | G1: Môn Văn | H1: Môn Anh | I1: Môn Lý | J1: Môn Hóa | K1: Đơn giá | L1: Tổng số lượt | M1: Tổng số tiền | N1: Số thu được | O1: Ct | P1: TH | Q1: TM | R1: Phí TM | S1: Đóng dư tiền | T1: Số TK | U1: Tên TK | V1: Tên NH | W1: Địa chỉ | Y1: Hóa đơn 29
A2: 1 | B2: 202510 | C2: Trần Bảo Duy(NVC) | D2: SV10Ax1 | E2: 10A | F2: 3 | G2: 0 | H2: 0 | I2: 3 | J2: 0 | K2: 100000 | L2: =SUM(F2:J2) -> 6 | M2: =L2*K2 -> 600000 | N2: =M2 -> 600000 | P2: FT25298961227128 | S2: =M2-N2 -> 0 | T2: 0670190997777 | U2: NGUYEN THI HUYEN | V2: Ngân hàng MB
A3: 2 | B3: 202510 | C3: Nguyễn Thu Quyên | D3: SV10x10x1 | E3: 10A10 | F3: 5 | G3: 0 | H3: 3 | I3: 0 | J3: 0 | K3: 100000 | L3: =SUM(F3:J3) -> 8 | M3: =L3*K3 -> 800000 | N3: =M3 -> 800000 | P3: FT25308083720010 | S3: =M3-N3 -> 0 | T3: 0670190997777 | U3: NGUYEN THI HUYEN | V3: Ngân hàng MB
A4: 3 | B4: 202510 | C4: Hoàng Thanh Phong | D4: SV10x10x10 | E4: 10A10 | F4: 0 | G4: 0 | H4: 3 | I4: 0 | J4: 0 | K4: 100000 | L4: =SUM(F4:J4) -> 3 | M4: =L4*K4 -> 300000 | N4: =M4 -> 300000 | P4: FT25304886272980 | S4: =M4-N4 -> 0 | T4: 0670190997777 | U4: NGUYEN THI HUYEN | V4: Ngân hàng MB
A5: 4 | B5: 202510 | C5: Trần Quỳnh Anh | D5: SV10x10x11 | E5: 10A10 | F5: 6 | G5: 0 | H5: 4 | I5: 0 | J5: 0 | K5: 100000 | L5: =SUM(F5:J5) -> 10 | M5: =L5*K5 -> 1000000 | N5: =M5 -> 1000000 | P5: FT25302377371602 | S5: =M5-N5 -> 0 | T5: 0670190997777 | U5: NGUYEN THI HUYEN | V5: Ngân hàng MB
A6: 5 | B6: 202510 | C6: Đoàn Minh Ánh | D6: SV10x10x12 | E6: 10A10 | F6: 6 | G6: 0 | H6: 4 | I6: 4 | J6: 0 | K6: 100000 | L6: =SUM(F6:J6) -> 14 | M6: =L6*K6 -> 1400000 | N6: =M6 -> 1400000 | P6: FT25296991204506 | S6: =M6-N6 -> 0 | T6: 0670190997777 | U6: NGUYEN THI HUYEN | V6: Ngân hàng MB
A7: 6 | B7: 202510 | C7: Lê Vũ Bảo Anh | D7: SV10x10x13 | E7: 10A10 | F7: 6 | G7: 0 | H7: 0 | I7: 0 | J7: 0 | K7: 100000 | L7: =SUM(F7:J7) -> 6 | M7: =L7*K7 -> 600000 | N7: =M7 -> 600000 | P7: FT25305649357438 | S7: =M7-N7 -> 0 | T7: 0670190997777 | U7: NGUYEN THI HUYEN | V7: Ngân hàng MB
A8: 7 | B8: 202510 | C8: Bùi Đức Hải Minh | D8: SV10x10x14 | E8: 10A10 | F8: 6 | G8: 0 | H8: 0 | I8: 0 | J8: 0 | K8: 100000 | L8: =SUM(F8:J8) -> 6 | M8: =L8*K8 -> 600000 | N8: =M8 -> 600000 | P8: FT25304410010058 | S8: =M8-N8 -> 0 | T8: 0670190997777 | U8: NGUYEN THI HUYEN | V8: Ngân hàng MB
A9: 8 | B9: 202510 | C9: Đặng Anh Thư | D9: SV10x10x15 | E9: 10A10 | F9: 6 | G9: 0 | H9: 0 | I9: 0 | J9: 0 | K9: 100000 | L9: =SUM(F9:J9) -> 6 | M9: =L9*K9 -> 600000 | N9: =M9 -> 600000 | P9: FT25304301883414 | S9: =M9-N9 -> 0 | T9: 0670190997777 | U9: NGUYEN THI HUYEN | V9: Ngân hàng MB
A10: 9 | B10: 202510 | C10: Đỗ Anh Thư | D10: SV10x10x16 | E10: 10A10 | F10: 6 | G10: 0 | H10: 0 | I10: 0 | J10: 0 | K10: 100000 | L10: =SUM(F10:J10) -> 6 | M10: =L10*K10 -> 600000 | N10: =M10 -> 600000 | P10: FT25301102720132 | S10: =M10-N10 -> 0 | T10: 0670190997777 | U10: NGUYEN THI HUYEN | V10: Ngân hàng MB
A11: 10 | B11: 202510 | C11: Đỗ Đăng Dũng | D11: SV10x10x17 | E11: 10A10 | F11: 4 | G11: 0 | H11: 0 | I11: 0 | J11: 0 | K11: 100000 | L11: =SUM(F11:J11) -> 4 | M11: =L11*K11 -> 400000 | N11: =M11 -> 400000 | P11: FT25308446820372 | S11: =M11-N11 -> 0 | T11: 0670190997777 | U11: NGUYEN THI HUYEN | V11: Ngân hàng MB
A12: 11 | B12: 202510 | C12: Đỗ Quang Minh | D12: SV10x10x2 | E12: 10A10 | F12: 6 | G12: 0 | H12: 4 | I12: 0 | J12: 0 | K12: 100000 | L12: =SUM(F12:J12) -> 10 | M12: =L12*K12 -> 1000000 | N12: =M12 -> 1000000 | P12: FT25296196925791 | S12: =M12-N12 -> 0 | T12: 0670190997777 | U12: NGUYEN THI HUYEN | V12: Ngân hàng MB
A13: 12 | B13: 202510 | C13: Đoàn Tuệ Anh | D13: SV10x10x3 | E13: 10A10 | F13: 0 | G13: 0 | H13: 3 | I13: 3 | J13: 0 | K13: 100000 | L13: =SUM(F13:J13) -> 6 | M13: =L13*K13 -> 600000 | N13: =M13 -> 600000 | P13: FT25296986073542 FT25296415045814 | S13: =M13-N13 -> 0 | T13: 0670190997777 | U13: NGUYEN THI HUYEN | V13: Ngân hàng MB
... A17: 16 | B17: 202510 | C17: Nguyễn Thanh Bình | D17: SV10x10x7 | E17: 10A10 | F17: 0 | G17: 0 | H17: 4 | I17: 4 | J17: 0 | K17: 100000 | L17: =SUM(F17:J17) -> 8 | M17: =L17*K17 -> 800000 | N17: =M17 -> 800000 | P17: FT25295710705788 | S17: =M17-N17 -> 0 | T17: 0670190997777 | U17: NGUYEN THI HUYEN | V17: Ngân hàng MB
A18: 17 | B18: 202510 | C18: Đào Xuân Bách | D18: SV10x10x8 | E18: 10A10 | F18: 0 | G18: 0 | H18: 2 | I18: 0 | J18: 0 | K18: 100000 | L18: =SUM(F18:J18) -> 2 | M18: =L18*K18 -> 200000 | N18: 200000 | P18: FT25295687224836 | S18: =M18-N18 -> 0 | T18: 0670190997777 | U18: NGUYEN THI HUYEN | V18: Ngân hàng MB
A19: 18 | B19: 202510 | C19: Nguyễn Đức Bảo | D19: SV10x10x9 | E19: 10A10 | F19: 0 | G19: 0 | H19: 4 | I19: 0 | J19: 0 | K19: 100000 | L19: =SUM(F19:J19) -> 4 | M19: =L19*K19 -> 400000 | N19: =M19 -> 400000 | P19: FT25298922961220 | S19: =M19-N19 -> 0 | T19: 0670190997777 | U19: NGUYEN THI HUYEN | V19: Ngân hàng MB
A20: 19 | B20: 202510 | C20: Đào Thu An | D20: SV10x12x1 | E20: 10A12 | F20: 6 | G20: 4 | H20: 5 | I20: 4 | J20: 0 | K20: 100000 | L20: =SUM(F20:J20) -> 19 | M20: =L20*K20 -> 1900000 | N20: =M20 -> 1900000 | P20: FT25300924002780 | S20: =M20-N20 -> 0 | T20: 0670190997777 | U20: NGUYEN THI HUYEN | V20: Ngân hàng MB
A21: 20 | B21: 202510 | C21: Ngô Phạm An Phương | D21: SV10x12x10 | E21: 10A12 | F21: 0 | G21: 4 | H21: 5 | I21: 0 | J21: 0 | K21: 100000 | L21: =SUM(F21:J21) -> 9 | M21: =L21*K21 -> 900000 | N21: =M21 -> 900000 | P21: FT25305848300230 | S21: =M21-N21 -> 0 | T21: 0670190997777 | U21: NGUYEN THI HUYEN | V21: Ngân hàng MB
A22: 21 | B22: 202510 | C22: Đoàn Minh Quân | D22: SV10x12x11 | E22: 10A12 | F22: 6 | G22: 4 | H22: 5 | I22: 4 | J22: 0 | K22: 100000 | L22: =SUM(F22:J22) -> 19 | M22: =L22*K22 -> 1900000 | N22: =M20 -> 1900000 | P22: FT25298392452070 | S22: =M22-N22 -> 0 | T22: 0670190997777 | U22: NGUYEN THI HUYEN | V22: Ngân hàng MB
A23: 22 | B23: 202510 | C23: Trịnh Hà Phương | D23: SV10x12x26 | E23: 10A12 | F23: 0 | G23: 0 | H23: 0 | I23: 4 | J23: 0 | K23: 100000 | L23: =SUM(F23:J23) -> 4 | M23: =L23*K23 -> 400000 | N23: 400000 | P23: FT25300736359970 | S23: =M23-N23 -> 0 | T23: 0670190997777 | U23: NGUYEN THI HUYEN | V23: Ngân hàng MB
A24: 23 | B24: 202510 | C24: Đinh Hoài An | D24: SV10x12x13 | E24: 10A12 | F24: 6 | G24: 4 | H24: 0 | I24: 4 | J24: 0 | K24: 100000 | L24: =SUM(F24:J24) -> 14 | M24: =L24*K24 -> 1400000 | N24: =M24 -> 1400000 | P24: FT25298909530186 | S24: =M24-N24 -> 0 | T24: 0670190997777 | U24: NGUYEN THI HUYEN | V24: Ngân hàng MB
A25: 24 | B25: 202510 | C25: Trần Ngọc Anh | D25: SV10x12x14 | E25: 10A12 | F25: 0 | G25: 0 | H25: 0 | I25: 4 | J25: 0 | K25: 100000 | L25: =SUM(F25:J25) -> 4 | M25: =L25*K25 -> 400000 | N25: =M25 -> 400000 | P25: FT25296621805260 | S25: =M25-N25 -> 0 | T25: 0670190997777 | U25: NGUYEN THI HUYEN | V25: Ngân hàng MB
A26: 25 | B26: 202510 | C26: Phạm Khánh Chi | D26: SV10x12x15 | E26: 10A12 | F26: 0 | G26: 4 | H26: 0 | I26: 4 | J26: 0 | K26: 100000 | L26: =SUM(F26:J26) -> 8 | M26: =L26*K26 -> 800000 | N26: =M26 -> 800000 | P26: FT25300002988295 | S26: =M26-N26 -> 0 | T26: 0670190997777 | U26: NGUYEN THI HUYEN | V26: Ngân hàng MB
A27: 26 | B27: 202510 | C27: Nguyễn Hương Giang | D27: SV10x12x16 | E27: 10A12 | F27: 6 | G27: 4 | H27: 0 | I27: 4 | J27: 0 | K27: 100000 | L27: =SUM(F27:J27) -> 14 | M27: =L27*K27 -> 1400000 | N27: =M27 -> 1400000 | P27: FT25302905129929 | S27: =M27-N27 -> 0 | T27: 0670190997777 | U27: NGUYEN THI HUYEN | V27: Ngân hàng MB
A28: 27 | B28: 202510 | C28: Nguyễn Ngọc Hân | D28: SV10x12x17 | E28: 10A12 | F28: 6 | G28: 4 | H28: 0 | I28: 4 | J28: 0 | K28: 100000 | L28: =SUM(F28:J28) -> 14 | M28: =L28*K28 -> 1400000 | N28: =M28 -> 1400000 | P28: FT25295881609578 | S28: =M28-N28 -> 0 | T28: 0670190997777 | U28: NGUYEN THI HUYEN | V28: Ngân hàng MB
A29: 28 | B29: 202510 | C29: Đỗ Hoàng Ngọc Huyền | D29: SV10x12x18 | E29: 10A12 | F29: 0 | G29: 3 | H29: 0 | I29: 4 | J29: 0 | K29: 100000 | L29: =SUM(F29:J29) -> 7 | M29: =L29*K29 -> 700000 | N29: =M29 -> 700000 | P29: FT25293930329127 | S29: =M29-N29 -> 0 | T29: 0670190997777 | U29: NGUYEN THI HUYEN | V29: Ngân hàng MB
A30: 29 | B30: 202510 | C30: Lê Kiến Huy | D30: SV10x12x19 | E30: 10A12 | F30: 0 | G30: 4 | H30: 0 | I30: 4 | J30: 0 | K30: 100000 | L30: =SUM(F30:J30) -> 8 | M30: =L30*K30 -> 800000 | N30: =M30 -> 800000 | P30: FT25296365210421 | S30: =M30-N30 -> 0 | T30: 0670190997777 | U30: NGUYEN THI HUYEN | V30: Ngân hàng MB
A31: 30 | B31: 202510 | C31: Vũ Nguyễn Khánh An | D31: SV10x12x2 | E31: 10A12 | F31: 0 | G31: 4 | H31: 5 | I31: 0 | J31: 0 | K31: 100000 | L31: =SUM(F31:J31) -> 9 | M31: =L31*K31 -> 900000 | N31: =M31 -> 900000 | P31: FT25309150131183 | S31: =M31-N31 -> 0 | T31: 0670190997777 | U31: NGUYEN THI HUYEN | V31: Ngân hàng MB
A32: 31 | B32: 202510 | C32: Lã Bảo Khánh | D32: SV10x12x20 | E32: 10A12 | F32: 6 | G32: 4 | H32: 0 | I32: 4 | J32: 0 | K32: 100000 | L32: =SUM(F32:J32) -> 14 | M32: =L32*K32 -> 1400000 | N32: =M32 -> 1400000 | P32: FT25294032533499 | S32: =M32-N32 -> 0 | T32: 0670190997777 | U32: NGUYEN THI HUYEN | V32: Ngân hàng MB
A33: 32 | B33: 202510 | C33: Nguyễn Nam Khánh | D33: SV10x12x21 | E33: 10A12 | F33: 0 | G33: 4 | H33: 0 | I33: 4 | J33: 0 | K33: 100000 | L33: =SUM(F33:J33) -> 8 | M33: =L33*K33 -> 800000 | N33: =M33 -> 800000 | P33: FT25294027788217 | S33: =M33-N33 -> 0 | T33: 0670190997777 | U33: NGUYEN THI HUYEN | V33: Ngân hàng MB
A34: 33 | B34: 202510 | C34: Nguyễn Phương Linh | D34: SV10x12x22 | E34: 10A12 | F34: 6 | G34: 4 | H34: 0 | I34: 4 | J34: 0 | K34: 100000 | L34: =SUM(F34:J34) -> 14 | M34: =L34*K34 -> 1400000 | N34: =M34 -> 1400000 | P34: FT25295671611439 | S34: =M34-N34 -> 0 | T34: 0670190997777 | U34: NGUYEN THI HUYEN | V34: Ngân hàng MB
A35: 34 | B35: 202510 | C35: Lê Nguyễn Khánh Ly | D35: SV10x12x23 | E35: 10A12 | F35: 0 | G35: 0 | H35: 0 | I35: 4 | J35: 0 | K35: 100000 | L35: =SUM(F35:J35) -> 4 | M35: =L35*K35 -> 400000 | N35: =M35 -> 400000 | P35: FT25296364002445 | S35: =M35-N35 -> 0 | T35: 0670190997777 | U35: NGUYEN THI HUYEN | V35: Ngân hàng MB
... A46: 46 | B46: 202510 | C46: Chu Vĩnh Hưng | D46: SV10x12x34 | E46: 10A12 | F46: 6 | G46: 0 | H46: 0 | I46: 0 | J46: 0 | K46: 100000 | L46: =SUM(F46:J46) -> 6 | M46: =L46*K46 -> 600000 | N46: =M46 -> 600000 | P46: FT25300241877910 | S46: =M46-N46 -> 0 | T46: 0670190997777 | U46: NGUYEN THI HUYEN | V46: Ngân hàng MB
A47: 47 | B47: 202510 | C47: Mai Thái Sơn | D47: SV10x12x35 | E47: 10A12 | F47: 0 | G47: 0 | H47: 0 | I47: 0 | J47: 0 | K47: 100000 | L47: 0 | M47: =L47*K47 -> 0 | S47: =M47-N47 -> 0 | T47: 0670190997777 | U47: NGUYEN THI HUYEN | V47: Ngân hàng MB
A48: 48 | B48: 202510 | C48: Nguyễn Tùng Lâm | D48: SV10x12x36 | E48: 10A12 | F48: 0 | G48: 3 | H48: 0 | I48: 0 | J48: 0 | K48: 100000 | L48: =SUM(F48:J48) -> 3 | M48: =L48*K48 -> 300000 | N48: 300000 | P48: FT25293400131266 | S48: =M48-N48 -> 0 | T48: 0670190997777 | U48: NGUYEN THI HUYEN | V48: Ngân hàng MB
A49: 49 | B49: 202510 | C49: Hà Minh Đức | D49: SV10x12x4 | E49: 10A12 | F49: 0 | G49: 4 | H49: 5 | I49: 4 | J49: 0 | K49: 100000 | L49: =SUM(F49:J49) -> 13 | M49: =L49*K49 -> 1300000 | N49: =M49 -> 1300000 | P49: FT25293249491606 | S49: =M49-N49 -> 0 | T49: 0670190997777 | U49: NGUYEN THI HUYEN | V49: Ngân hàng MB
A50: 50 | B50: 202510 | C50: Bùi Phúc Hưng | D50: SV10x12x5 | E50: 10A12 | F50: 6 | G50: 4 | H50: 5 | I50: 4 | J50: 0 | K50: 100000 | L50: =SUM(F50:J50) -> 19 | M50: =L50*K50 -> 1900000 | N50: =M50 -> 1900000 | P50: FT25304836340440 | S50: =M50-N50 -> 0 | T50: 0670190997777 | U50: NGUYEN THI HUYEN | V50: Ngân hàng MB
A51: 51 | B51: 202510 | C51: Hoàng Trung Kiên | D51: SV10x12x6 | E51: 10A12 | F51: 6 | G51: 4 | H51: 5 | I51: 4 | J51: 0 | K51: 100000 | L51: =SUM(F51:J51) -> 19 | M51: =L51*K51 -> 1900000 | N51: =M51 -> 1900000 | P51: FT25298552186928 | S51: =M51-N51 -> 0 | T51: 0670190997777 | U51: NGUYEN THI HUYEN | V51: Ngân hàng MB
A52: 52 | B52: 202510 | C52: Ngô Duy Minh | D52: SV10x12x7 | E52: 10A12 | F52: 6 | G52: 4 | H52: 5 | I52: 4 | J52: 0 | K52: 100000 | L52: =SUM(F52:J52) -> 19 | M52: =L52*K52 -> 1900000 | N52: =M52 -> 1900000 | P52: FT25296882675103 | S52: =M52-N52 -> 0 | T52: 0670190997777 | U52: NGUYEN THI HUYEN | V52: Ngân hàng MB
A53: 53 | B53: 202510 | C53: Nguyễn Vũ Bảo Minh | D53: SV10x12x8 | E53: 10A12 | F53: 0 | G53: 0 | H53: 5 | I53: 4 | J53: 0 | K53: 100000 | L53: =SUM(F53:J53) -> 9 | M53: =L53*K53 -> 900000 | N53: =M53 -> 900000 | P53: FT25294145090776 | S53: =M53-N53 -> 0 | T53: 0670190997777 | U53: NGUYEN THI HUYEN | V53: Ngân hàng MB
...

Sheet CT
F1: SAO KÊ CHI TIẾT TÀI KHOẢN Account Statement | O1: NGÂN HÀNG TMCP QUÂN ĐỘI Military Commercial Joint Stock Bank
F2: Từ ngày/From:15/10/2025 00:00:00 Đến ngày/To:23/10/2025 23:59:59 | O2: Chi nhánh/Branch: VN0010060 - Dong Ha Noi
A4: Tên khách hàng/Customer name: CONG TY TNHH TRI THUC SAO VIET Mã khách hàng/Customer code: 37285976 Địa chỉ/Address: SO 5 HEM 197/318/7 DUONG THACH BAN-PHUONG THACH BAN-QUAN LONG BIEN-THANH PHO HA NOI-VIET NAM | Q4: Tài khoản/Account No: 2588666868 Mã số thuế/Tax code: 0110940616 Loại tiền/Currency: VND
C6: Chúng tôi xin thông báo chi tiết phát sinh nợ/có trên tài khoản quý khách trong thời gian trên như sau: We would like to inform you about your account debit/credit transactions as the following details: Số dư đầu kỳ/ Opening Balance: 78,946,894 VND
A7: STT | D7: NGÀY GIAO DỊCH | G7: NGÀY HẠCH TOÁN | H7: PHÁT SINH NỢ | I7: PHÁT SINH CÓ | J7: SỐ DƯ | L7: ĐƠN VỊ THỤ HƯỞNG/ĐƠN VỊ CHUYỂN | M7: NỘI DUNG | R7: BÚT TOÁN
A8: 1 | D8: 10/11/2025 19:31:47 | G8: 10/11/2025 | H8: 0 | I8: 1,400,000 | J8: 75,222,160 | L8: SHBMB | M8: Luu Tram Anh SV12x3x1 thang 10 Ma giao dich Trace463192 Trace 46319 | R8: FT25314653040894
A9: 3 | D9: 07/11/2025 07:51:50 | G9: 07/11/2025 | H9: 0 | I9: 900,000 | J9: 246,308,960 | L9: PHAM THI THANH THUY | M9: Nguyen An Phuong SV12x2x31 thang 10 | R9: FT25311405411089
A10: 1 | D10: 06/11/2025 20:03:17 | G10: 06/11/2025 | H10: 0 | I10: 2,600,000 | J10: 245,408,960 | L10: NGUYEN NGOC LAN | M10: MBVCB.11613275362.813368.Nguyen Duc Minh SV12x3x34 thang 10.CT tu 9358 832572 NGUYEN NGOC LAN toi 25886668 68 CONG TY TNHH TRI THUC SAO VIET t ai MB- Ma GD ACSP/ hb813368 | R10: FT25310200056333
A11: 1 | D11: 05/11/2025 21:57:54 | G11: 05/11/2025 | H11: 0 | I11: 900,000 | J11: 242,808,960 | L11: VND-TGTT-BUI THI KIM OANH | M11: Nguyen Bui Minh Duc SV11x3x25 thang 10 FT25310088398630 Ma giao dich Trace530832 Trace 530832 | R11: FT25309710796213
A12: 1 | D12: 05/11/2025 19:56:18 | G12: 05/11/2025 | H12: 0 | I12: 800,000 | J12: 241,908,960 | L12: LUONG HA THANH | M12: Lai Duc Khanh SV12x6x25 thang 10 | R12: FT25309423040360
A13: 2 | D13: 05/11/2025 18:47:34 | G13: 05/11/2025 | H13: 0 | I13: 700,000 | J13: 241,108,960 | L13: LE THI THUY DUONG | M13: Ho Duc Viet SV12x6x22 thang 10 FT25 309904680821 Ma giao dich Trace3 23956 Trace 323956 | R13: FT25309333190597
A14: 1 | D14: 04/11/2025 23:26:59 | G14: 05/11/2025 | H14: 0 | I14: 900,000 | J14: 240,408,960 | L14: VND-TGTT-NGUYEN THANH HANG | M14: Hoang Minh Huy SV12x2x7 thang 10 FT 25309750063262 Ma giao dich Trac e358271 Trace 358271 | R14: FT25309015020433
A15: 2 | D15: 04/11/2025 22:04:37 | G15: 05/11/2025 | H15: 0 | I15: 1,800,000 | J15: 239,508,960 | L15: NGUYEN VAN KIEU | M15: VO QUANG MINH SV12X2X25 THANG 10- M a GD ACSP/ WV195701 | R15: FT25309847961096
A16: 3 | D16: 04/11/2025 21:43:08 | G16: 04/11/2025 | H16: 0 | I16: 900,000 | J16: 237,708,960 | L16: NGUYEN TRUONG SON | M16: NGUYEN NGOC ANH SV12X2X35 THANG 10- Ma GD ACSP/ 2b095573 | R16: FT25308316553593
A17: 4 | D17: 04/11/2025 21:00:54 | G17: 04/11/2025 | H17: 0 | I17: 900,000 | J17: 236,808,960 | L17: PHAN VAN THANG | M17: Phan Truong Giang SV12x2x28 thang 1 0 | R17: FT25308259278932
A18: 5 | D18: 04/11/2025 20:55:07 | G18: 04/11/2025 | H18: 0 | I18: 1,800,000 | J18: 235,908,960 | L18: HO KINH DOANH THY HUONG | M18: QR Nguyen Minh Quan SV12x2x24 tha ng 10- Ma GD ACSP/ br659732 | R18: FT25308064027205
... A41: 21 | D41: 30/10/2025 21:00:31 | G41: 30/10/2025 | H41: 0 | I41: 2,700,000 | J41: 211,548,381 | L41: MAI THI THANH QUYNH | M41: MBVCB.11518187411.397232.Do Thu Hie n SV12x1x8 TT hoc them T10 .CT tu 0 021000321578 MAI THI THANH QUYNH to i 2588666868 CONG TY TNHH TRI THUC SAO VIET tai MB- Ma GD ACSP/ fu397232 | R41: FT25303094555430
A42: 22 | D42: 30/10/2025 19:03:38 | G42: 30/10/2025 | H42: 0 | I42: 900,000 | J42: 208,848,381 | L42: CONG TY CO PHAN ZION | M42: ZALOPAY-CHUYENTIEN-O5CH7BKSPCLU-con The Anh dong tien hoc | R42: FT25303048630587 | U42: SV12x5x31
A43: 23 | D43: 30/10/2025 13:01:14 | G43: 30/10/2025 | H43: 0 | I43: 1,300,000 | J43: 207,948,381 | L43: LE VAN KHOA | M43: MBVCB.11511851679.229561.LE Thai D uy SV12x5x5 thang 10.CT tu 00210010 29533 LE VAN KHOA toi 2588666868 CO NG TY TNHH TRI THUC SAO VIET tai MB - Ma GD ACSP/ ce229561 | R43: FT25303430012344
A44: 24 | D44: 30/10/2025 11:07:53 | G44: 30/10/2025 | H44: 0 | I44: 1,400,000 | J44: 206,648,381 | L44: DINH HA ANH | M44: Dinh Ha Anh SV12x6x3 thang 10 | R44: FT25303249088520
A45: 25 | D45: 30/10/2025 10:32:29 | G45: 30/10/2025 | H45: 0 | I45: 2,200,000 | J45: 205,248,381 | L45: NGUYEN THI THUY | M45: NGUYEN DAN THU SV12x5x11 thang 10 Ma giao dich Trace423008 Trace 42 3008 | R45: FT25303943908805
A46: 26 | D46: 30/10/2025 05:38:04 | G46: 30/10/2025 | H46: 0 | I46: 1,000,000 | J46: 203,048,381 | L46: TRAN THANH HUNG | M46: MBVCB.11507485097.298870.tran duc a nh nop tien hoc t10/2025.CT tu 001 1000507585 TRAN THANH HUNG toi 2588 666868 CONG TY TNHH TRI THUC SAO VI ET tai MB- Ma GD ACSP/ df298870 | R46: FT25303302379944
A47: 27 | D47: 30/10/2025 01:34:33 | G47: 30/10/2025 | H47: 0 | I47: 900,000 | J47: 202,048,381 | L47: NGUYEN HUYEN NGA | M47: Phan Ngoc Ha SV12x2x4 thang 10 Ma giao dich Trace451177 Trace 45117 | R47: FT25303574185251
A48: 28 | D48: 29/10/2025 22:31:32 | G48: 29/10/2025 | H48: 0 | I48: 1,500,000 | J48: 201,148,381 | L48: PHAM THI THUY HANG | M48: MBVCB.11506704851.761721.Phan Quoc Tri SV12x2x22 thang 10.CT tu 001100 3661439 PHAM THI THUY HANG toi 2588 666868 CONG TY TNHH TRI THUC SAO VI ET tai MB- Ma GD ACSP/ nv761721 | R48: FT25302036202464
A49: 29 | D49: 29/10/2025 19:35:07 | G49: 29/10/2025 | H49: 0 | I49: 900,000 | J49: 199,648,381 | L49: NGUYEN THI KIM DUNG | M49: Le Duc Anh SV12x1x3 thang 10 291025 19 35 06 414377 Ma giao dich Tr ace414377 Trace 414377 | R49: FT25302395191088
A50: 30 | D50: 29/10/2025 18:43:11 | G50: 29/10/2025 | H50: 0 | I50: 1,400,000 | J50: 198,748,381 | L50: VU THU NGA | M50: Thai Thanh Thu SV12x6x17 thang 10 | R50: FT25302510844003
A51: 31 | D51: 29/10/2025 18:25:06 | G51: 29/10/2025 | H51: 0 | I51: 800,000 | J51: 197,348,381 | L51: VND-TGTT-TRAN THI HAU | M51: Tran Minh Quang 12A6 Thang 10 FT2 5302638538700 Ma giao dich Trace 610886 Trace 610886 | R51: FT25302567440772
A52: 32 | D52: 29/10/2025 17:39:35 | G52: 29/10/2025 | H52: 0 | I52: 1,800,000 | J52: 196,548,381 | L52: TRAN THI THANH HOA | M52: NGUYEN GIA NAM SV12X2X9 THANG 10- M a GD ACSP/ fz595972 | R52: FT25302023061045
A53: 33 | D53: 29/10/2025 17:39:18 | G53: 29/10/2025 | H53: 0 | I53: 1,700,000 | J53: 194,748,381 | L53: DONG THI NHUNG | M53: Dong Thi Nhung SV12x5x25 thang 10 | R53: FT25302224972728
A54: 34 | D54: 29/10/2025 11:04:27 | G54: 29/10/2025 | H54: 0 | I54: 2,200,000 | J54: 193,048,381 | L54: VND-TGTT-DO THI HAI YEN | M54: Pham Anh Vu SV12x5x13 thang 10 FT25 302790756070 Ma giao dich Trace9 61046 Trace 961046 | R54: FT25302047179677
A55: 35 | D55: 28/10/2025 22:14:47 | G55: 28/10/2025 | H55: 0 | I55: 1,800,000 | J55: 190,848,381 | L55: SACOMBANK | M55: IBFT Ngo Quang Tung SV12x2x15 thang 10 Ma giao dich Trace932763 Tra ce 932763 | R55: FT25301829647047
A56: 36 | D56: 28/10/2025 21:14:03 | G56: 28/10/2025 | H56: 0 | I56: 900000 | J56: 189,048,381 | L56: VND-TGTT-HA LAN PHUONG | M56: Tranminhtri 12a1 FT25301070418208 Ma giao dich Trace846244 Trace 84 6244 | R56: FT25301531016440
A57: 37 | D57: 28/10/2025 21:12:38 | G57: 28/10/2025 | H57: 0 | I57: 2500000 | J57: 188,148,381 | L57: PHAM THI NGA | M57: Ta Thanh Van SV12x3x24 thang 10 | R57: FT25301036200259
A58: 38 | D58: 28/10/2025 21:00:41 | G58: 28/10/2025 | H58: 0 | I58: 900000 | J58: 185,648,381 | L58: LE THUY TRANG | M58: LE THUY TRANG 12A1 nop tien hoc tha ng 10 | R58: FT25301784198879
A59: 39 | D59: 28/10/2025 18:30:17 | G59: 28/10/2025 | H59: 0 | I59: 1300000 | J59: 184,748,381 | L59: NGUYEN THI LANH | M59: DUONG DINH LOI SV12X3X33 THANG 10- Ma GD ACSP/ eV766902 | R59: FT25301710270015
A60: 40 | D60: 28/10/2025 14:25:18 | G60: 28/10/2025 | H60: 0 | I60: 900000 | J60: 183,448,381 | L60: NGUYEN THI BICH PHUONG | M60: Than Tue Minh SV12x2x29 thang 10 | R60: FT25301370908047
A61: 41 | D61: 28/10/2025 10:04:07 | G61: 28/10/2025 | H61: 0 | I61: 1400000 | J61: 182,548,381 | L61: LE KIM TRINH | M61: Vu le bao chau sv12x6x5 thang 10 FT 25301805065643 Ma giao dich Trac e818901 Trace 818901 | R61: FT25301407237925
A62: 42 | D62: 28/10/2025 09:14:25 | G62: 28/10/2025 | H62: 0 | I62: 1400000 | J62: 181,148,381 | L62: LE HUY HAI | M62: LE DUC TRUNG SV12X6X21 THANG 10- Ma GD ACSP/ w7125280 | R62: FT25301011060862
A63: 43 | D63: 28/10/2025 06:48:02 | G63: 28/10/2025 | H63: 0 | I63: 2500000 | J63: 179,748,381 | L63: VND-TGTT-HOANG THI XUYEN | M63: Nguyen Hoang Ha An SV12x3x25 thang 10 FT25301216703890 Ma giao dich Trace876152 Trace 876152 | R63: FT25301341850807
A64: 44 | D64: 27/10/2025 20:45:15 | G64: 27/10/2025 | H64: 0 | I64: 2300000 | J64: 177,248,381 | L64: TRAN THI HONG THANH | M64: QR Nguyen Duc Phuong SV12x3x5 tha ng 10- Ma GD ACSP/ Ai633749 | R64: FT25300791430302
...

Sheet TH
B1: Signature Not Verified Da ky boi Ngan hang TMCP Quan doi. Ngay ky : Wed Oct 22 12:53:26 ICT 2025 SỔ PHỤ CHI TIẾT KIÊM BÁO NỢ/BÁO CÓ NGÂN HÀNG TMCP QUÂN ĐỘI Account Statement/Debit/Credit transaction Military Commercial Joint Stock Bank
B2: Số tài khoản/Account No: 0670190997777 Tên tài khoản/Account name: NGUYEN THI HUYEN Loại tiền/Currency: VND Kỳ sao kê/Statement period: Từ ngày/From: 10/10/2025 Đến ngày/To: 22/10/2025
B3: Chúng tôi xin thông báo chi tiết phát sinh nợ/có trên tài khoản quý khách trong thời gian trên như sau: We would like to inform you about your account debit/credit transactions as the following details:
A6: ATT | B6: Ngày giao dịch Transaction Date | C6: Số bút toán Transaction No | D6: Phát sinh nợ Debit | E6: Phát sinh có Credit | F6: Nội dung Details | G6: Đơn vị thụ hưởng/Đơn vị chuyển Beneficiary/Applicant | H6: Tài khoản Account | I6: Ngân hàng đối tác Remitter Bank
B7: 07/11/2025 08:36 | C7: FT25311646938538 | D7: 0 | E7: 900000 | F7: LUONG THI THU TRANG QR Nguyen Minh Anh SV10x1x1 thang 10- Ma GD ACSP/ A9433002 | G7: NGUYEN THI HUYEN | H7: 670190997777 | I7: MB
B8: 06/11/2025 20:26 | C8: FT25310850357981 | D8: 0 | E8: 800000 | F8: CUSTOMER Nguyen Ha Vy SV12x9x9 thang 10 0611 25 20 26 47 014646 Ma giao dich Trace014646 Trace 014646 | G8: NGUYEN THI HUYEN | H8: 670190997777 | I8: MB
B9: 06/11/2025 18:44 | C9: FT25310212719476 | D9: 0 | E9: 800000 | F9: LE THI ANH QR Dao Quynh Huong SV10x5x4 thang 10- Ma GD ACSP/ jv220875 | G9: NGUYEN THI HUYEN | H9: 670190997777 | I9: MB
B10: 06/11/2025 12:17 | C10: FT25310091500601 | D10: 0 | E10: 500000 | F10: CHU THI HOA MBVCB.11606150212.502622.Mai Truong Giang SV10x14x2 thang 10.CT tu 054 1000177955 CHU THI HOA toi 06701909 97777 NGUYEN THI HUYEN tai MB- Ma G | G10: NGUYEN THI HUYEN | H10: 670190997777 | I10: MB
B11: 06/11/2025 12:04 | C11: FT25310268801899 | D11: 0 | E11: 900000 | F11: CUSTOMER Tran Yen Nhi SV10x14x9 thang 10. TU: NGUYEN THI THU HUONG | G11: NGUYEN THI HUYEN | H11: 670190997777 | I11: MB
B12: 06/11/2025 11:18 | C12: FT25310745533139 | D12: 0 | E12: 500000 | F12: HOANG THI LIEN QR Nguyen Hoang Ngan SV10x14x7 th ang 10- Ma GD ACSP/ 8k591211 | G12: NGUYEN THI HUYEN | H12: 670190997777 | I12: MB
B13: 05/11/2025 23:33 | C13: FT25310192656078 | D13: 0 | E13: 700000 | F13: DAO THE TUAN MBVCB.11600665858.103329.Dao Thi Ma i Anh N.V.Cu SV 10.3.51 chuyen ti en.CT tu 1029662853 DAO THE TUAN to i 0670190997777 NGUYEN THI HUYEN ta | G13: NGUYEN THI HUYEN | H13: 670190997777 | I13: MB
B14: 05/11/2025 19:08 | C14: FT25309210450052 | D14: 0 | E14: 1300000 | F14: CUSTOMER Bui Phuong Thao SV10x14x13 thang 10. TU: BUI VAN TUONG | G14: NGUYEN THI HUYEN | H14: 670190997777 | I14: MB
B15: 05/11/2025 17:23 | C15: FT25309036004965 | D15: 0 | E15: 800000 | F15: CUSTOMER Dinh Nguyen Duong SV11x1x16 thang 1 0 FT25309027080130 Ma giao dich Trace638874 Trace 638874 | G15: NGUYEN THI HUYEN | H15: 670190997777 | I15: MB
B16: 05/11/2025 16:47 | C16: FT25309150131183 | D16: 0 | E16: 900000 | F16: VU PHUONG NAM VU NGUYEN KHANH AN SV10X12X2 THANG 10- Ma GD ACSP/ gD746328 | G16: NGUYEN THI HUYEN | H16: 670190997777 | I16: MB
B17: 05/11/2025 15:40 | C17: FT25309797540820 | D17: 0 | E17: 600000 | F17: TRAN THANH LOAN QR Tran Nhat Nam SV12x7x4 thang 1 0- Ma GD ACSP/ Cj834731 | G17: NGUYEN THI HUYEN | H17: 670190997777 | I17: MB
A18: 1 | B18: 05/11/2025 08:29 | C18: FT25309266316630 | D18: 0 | E18: 500000 | F18: LE THI HIEN QR Pham Thu Huong SV10x7x9 thang 10- Ma GD ACSP/ 3K476369 | G18: NGUYEN THI HUYEN | H18: 670190997777 | I18: MB
A19: 2 | B19: 05/11/2025 08:24 | C19: FT25309160722352 | D19: 0 | E19: 800000 | F19: PHAM THI KIM HOA MBVCB.11587030617.845416.Do Tuan Mi nh SV12x9x11 thang 10.CT tu 1017167 332 PHAM THI KIM HOA toi 0670190997 777 NGUYEN THI HUYEN tai MB- Ma GD | G19: NGUYEN THI HUYEN | H19: 670190997777 | I19: MB
A20: 3 | B20: 05/11/2025 08:17 | C20: FT25309140205867 | D20: 0 | E20: 400000 | F20: NGUYEN THI THU HUYEN MBVCB.11586955396.791050. Nguyen Phu ong Anh SV10x14x20 thang 10.CT tu 1 023105610 NGUYEN THI THU HUYEN toi 0670190997777 NGUYEN THI HUYEN tai | G20: NGUYEN THI HUYEN | H20: 670190997777 | I20: MB
A21: 4 | B21: 05/11/2025 06:07 | C21: FT25309040656982 | D21: 0 | E21: 800000 | F21: VU HUYEN HANH MBVCB.11585692740.990790.Do Vu Ba L inh SV11x4x1 thang 10.CT tu 0011001 386041 VU HUYEN HANH toi 0670190997 777 NGUYEN THI HUYEN tai MB- Ma GD | G21: NGUYEN THI HUYEN | H21: 670190997777 | I21: MB
A22: 5 | B22: 04/11/2025 23:42 | C22: FT25309890073971 | D22: 0 | E22: 800000 | F22: CUSTOMER Pham Hoang Minh SV11x7x3 thang 10 F T25309007223058 Ma giao dich Tra ce387703 Trace 387703 | G22: NGUYEN THI HUYEN | H22: 670190997777 | I22: MB
A23: 6 | B23: 04/11/2025 22:46 | C23: FT25309878431400 | D23: 0 | E23: 2400000 | F23: CUSTOMER PHAN THI MINH NGUYET chuyen Nguyen Bao Viet SV12x4x6 thang 10 FT253093 10140091 Ma giao dich Trace25663 8 Trace 256638 | G23: NGUYEN THI HUYEN | H23: 670190997777 | I23: MB
A24: 7 | B24: 04/11/2025 22:42 | C24: FT25309350952559 | D24: 0 | E24: 1100000 | F24: CUSTOMER Nguyen Van Tuan SV12x8x13 thang 10 FT25309146345065 Ma giao dich Tr ace246151 Trace 246151 | G24: NGUYEN THI HUYEN | H24: 670190997777 | I24: MB
A25: 8 | B25: 04/11/2025 22:22 | C25: FT25309220426209 | D25: 0 | E25: 500000 | F25: ZION ZALOPAY-CHUYENTIEN-O5CH7BMCK1PB-Din h Minh Dang SV12x7x6 thang 10. TU: ZION | G25: NGUYEN THI HUYEN | H25: 670190997777 | I25: MB
A26: 9 | B26: 04/11/2025 22:13 | C26: FT25309480081186 | D26: 0 | E26: 600000 | F26: NGUYEN VIET HAI NGUYEN VIET HAI Chuyen tien em Duc Anh mon Anh- Ma GD ACSP/ Y3848274 | G26: NGUYEN THI HUYEN | H26: 670190997777 | I26: MB | J26: Nguyễn Việt Đức Anh | K26: SV12x7x1
A27: 10 | B27: 04/11/2025 21:59 | C27: FT25308700570767 | D27: 0 | E27: 700000 | F27: DUONG THI THU HANG HOANG THU THUY NVC SV11. 3.42 DONG T IEN THANG 10- Ma GD ACSP/ RD174356 | G27: NGUYEN THI HUYEN | H27: 670190997777 | I27: MB
A28: 11 | B28: 04/11/2025 21:55 | C28: FT25308728272670 | D28: 0 | E28: 300000 | F28: CUSTOMER HOANG THI SUONG chuyen tien. TU: HOANG THI SUONG | G28: NGUYEN THI HUYEN | H28: 670190997777 | I28: MB | J28: Ngỗ Hải Anh | K28: 11A11
A29: 12 | B29: 04/11/2025 21:39 | C29: FT25308878760240 | D29: 0 | E29: 800000 | F29: CUSTOMER Quach Ngoc Tuan SV12x8x18 thang 10 Ma giao dich Trace419972 Trace 4 19972 | G29: NGUYEN THI HUYEN | H29: 670190997777 | I29: MB
A30: 13 | B30: 04/11/2025 21:00 | C30: FT25308047834781 | D30: 0 | E30: 1000000 | F30: NGUYEN THI HIEN NGUYEN HOANG NAM SV11X1X2 THANG 10- Ma GD ACSP/ pB853950 | G30: NGUYEN THI HUYEN | H30: 670190997777 | I30: MB
A31: 14 | B31: 04/11/2025 20:53 | C31: FT25308542788499 | D31: 0 | E31: 800000 | F31: LE THI LAN QR Nguyen Ngoc Bao Tram SV12x9x9 thang 10- Ma GD ACSP/ rV654894 | G31: NGUYEN THI HUYEN | H31: 670190997777 | I31: MB
A32: 15 | B32: 04/11/2025 20:46 | C32: FT25308680911398 | D32: 0 | E32: 400000 | F32: ZION ZALOPAY-CHUYENTIEN-O5CH7BMCHOSC-Tra n Duc Anh SV10x8x2 thang 10. TU: ZION | G32: NGUYEN THI HUYEN | H32: 670190997777 | I32: MB
A33: 16 | B33: 04/11/2025 20:16 | C33: FT25308567996616 | D33: 0 | E33: 800000 | F33: CUSTOMER Nguyen Quoc Hung SV12x4x19 thang 10 FT25308800049097 Ma giao dich T race535794 Trace 535794 | G33: NGUYEN THI HUYEN | H33: 670190997777 | I33: MB
A34: 17 | B34: 04/11/2025 19:59 | C34: FT25308546259469 | D34: 0 | E34: 800000 | F34: CUSTOMER Bui Duc Nhat Minh SV10x5x5 thang 10 FT25308214308386 Ma giao dich T race432833 Trace 432833 | G34: NGUYEN THI HUYEN | H34: 670190997777 | I34: MB
A35: 18 | B35: 04/11/2025 19:34 | C35: FT25308070363014 | D35: 0 | E35: 700000 | F35: CUSTOMER con Dinh Vu Ha Anh nop tien t10. TU: VU THI HA | G35: NGUYEN THI HUYEN | H35: 670190997777 | I35: MB
A36: 19 | B36: 04/11/2025 19:17 | C36: FT25308844392209 | D36: 0 | E36: 1200000 | F36: QUAN THUY DUONG QR Trinh Ngoc Nguyen Khang SV12x1 6x20 thang 10- Ma GD ACSP/ L1319560 | G36: NGUYEN THI HUYEN | H36: 670190997777 | I36: MB
A37: 20 | B37: 04/11/2025 19:08 | C37: FT25308862069941 | D37: 0 | E37: 900000 | F37: CUSTOMER Luu Tra My SV12x11x29 thang 10 FT25 308295030794 Ma giao dich Trace0 85600 Trace 085600 | G37: NGUYEN THI HUYEN | H37: 670190997777 | I37: MB
A38: 21 | B38: 04/11/2025 19:06 | C38: FT25308429538416 | D38: 0 | E38: 300000 | F38: DO THANH TRUNG MB 0670190997777 Do Tuan Anh SV11x8 x15 thang 10- Ma GD ACSP/ 8I073308 | G38: NGUYEN THI HUYEN | H38: 670190997777 | I38: MB
A39: 22 | B39: 04/11/2025 19:03 | C39: FT25308384080295 | D39: 0 | E39: 900000 | F39: CUSTOMER Ngo Gia Bao Nhi SV11x6x28 thang 10 Ma giao dich Trace925085 Trace 9 25085 | G39: NGUYEN THI HUYEN | H39: 670190997777 | I39: MB
A40: 23 | B40: 04/11/2025 18:34 | C40: FT25308931040379 | D40: 0 | E40: 600000 | F40: CUSTOMER Truong Ba Bao Nam SV11x8x12 thang 1 0. TU: TRAN THI THU THUAN | G40: NGUYEN THI HUYEN | H40: 670190997777 | I40: MB
... A73: 56 | B73: 03/11/2025 19:36 | C73: FT25307836767802 | D73: 0 | E73: 300000 | F73: NGUYEN THI VAN ANH NGUYEN KHANH LINH SV11X11X8 THANG 1 0- Ma GD ACSP/ gK953313 | G73: NGUYEN THI HUYEN | H73: 670190997777 | I73: MB
A74: 57 | B74: 03/11/2025 19:05 | C74: FT25307502224197 | D74: 0 | E74: 1157000 | F74: CUSTOMER con Ngo Kim Ngan 10a2 nop. TU: NGUYEN THI DUONG | G74: NGUYEN THI HUYEN | H74: 670190997777 | I74: MB | J74: dư 1,157k
...

Sheet Data_HS t5
A1: Stt | B1: Hovaten | C1: ID_Lop
A2: 1 | B2: Nguyễn Đăng Khôi | C2: SV10.1.1 | D2: 14/07/2009 | E2: Nam | F2: 0921916686 | G2: Nguyễn Tiến Mạnh | H2: 0913123399 | I2: Nguyễn Thị Quỳnh Hương | J2: 0921916686 | K2: Tổ dân phố số 14, Phường Việt Hưng, Quận Long Biên, Thành phố Hà Nội
A3: 2 | B3: Nguyễn Gia Kỳ | C3: SV10.1.2 | D3: 22/08/2009 | E3: Nam | F3: 0978392117 | G3: Nguyễn Đức Cường | H3: 0915190258 | I3: Chu Thị Mỹ Châu | J3: 0978392117 | K3: Tổ dân phố số 10, Phường Cự Khối, Quận Long Biên, Thành phố Hà Nội
A4: 3 | B4: Hoàng Minh Quân | C4: SV10.1.3 | D4: 30/09/2009 | E4: Nam | F4: 0943606816 | G4: Hoàng Văn Quyền | H4: 0915830909 | I4: Đặng Quỳnh Trang | J4: 0943606816 | K4: Tổ dân phố số 1, Phường Cự Khối, Quận Long Biên, Thành phố Hà Nội
A5: 4 | B5: Phạm Chí Thiên | C5: SV10.1.4 | D5: 01/09/2009 | E5: Nam | F5: 0774299474 | G5: Phạm Văn An | H5: 0908780506 | I5: Nguyễn Thị Như Quỳnh | J5: 0774299474 | K5: Tổ dân phố số 2, Phường Ngọc Lâm, Quận Long Biên, Thành phố Hà Nội
A6: 5 | B6: Nguyễn Vũ Minh Anh | C6: SV10.1.5 | D6: 13/05/2009 | E6: Nữ | F6: 0982790289 | G6: Nguyễn Minh Mẫn | H6: 0 | I6: Vũ Hồng Giang | J6: 0982790289 | K6: Phường Ngọc Lâm, Quận Long Biên, Thành phố Hà Nội
I7: Trương Thị Tho | J7: 0902124589 | K7: Tổ dân phố 6, Phường Trúc Bạch, Quận Ba Đình, Thành phố Hà Nội
I8: Nguyễn Thị Mai | J8: 0898575223 | K8: Tổ dân phố An Lạc, Thị trấn Trâu Quỳ, Huyện Gia Lâm, Thành phố Hà Nội
I9: Chu Thị Thu Hương | J9: 0967351852 | K9: Tổ dân phố số 1, Phường Cự Khối, Quận Long Biên, Thành phố Hà Nội
I10: Trần Hồng Minh | J10: 0865495521 | K10: Phường Thạch Bàn, Quận Long Biên, Thành phố Hà Nội
I11: Dương Thị Tuyết Trinh | J11: 0399363261 | K11: Phường Thạch Bàn, Quận Long Biên, Thành phố Hà Nội
I16: Nguyễn Thị Hằng | J16: 0983310980 | K16: Tổ dân phố số 15, Phường Sài Đồng, Quận Long Biên, Thành phố Hà Nội
I17: Đỗ Thị Phương | J17: 0942479345 | K17: Tổ dân phố số 1, Phường Cự Khối, Quận Long Biên, Thành phố Hà Nội
I18: Lưu Phương Dung | J18: 0975375588 | K18: Phường Việt Hưng, Quận Long Biên, Thành phố Hà Nội
I19: Vũ Thị Thu Hương | J19: 0862793108 | K19: Tổ dân phố số 4, Xã Đặng Xá, Huyện Gia Lâm, Thành phố Hà Nội
I20: Nguyễn Thị Bích Phương | J20: 0915225659 | K20: Phường Đức Giang, Quận Long Biên, Thành phố Hà Nội
I21: Trần Thị Huyền | J21: 0985477918 | K21: Tổ dân phố số 7, Phường Ngọc Thụy, Quận Long Biên, Thành phố Hà Nội
I22: Nguyễn Thị Hiền | J22: 0961227887 | K22: Phường Sài Đồng, Quận Long Biên, Thành phố Hà Nội
... I28: ĐỖ THỊ HOA | J28: 0947246556 | K28: 29 ngõ 71 tổ 4 thạch bàn long biên hà nôi
I29: #N/A | J29: #N/A | K29: #N/A
I30: Nguyễn Thị Thanh Thủy | J30: 0946228884 | K30: Tổ 9 - Thạch Bàn - Long Biên- Hà Nội
I31: #N/A | J31: #N/A | K31: #N/A
I32: NGÔ THỊ THANH HƯƠNG | J32: 0397661482 | K32: Tổ 10, Phường Thạch Bàn, Quận Long Biên, TP Hà Nội
I33: Nguyễn Thị Trà Giang | J33: 0366879386 | K33: Tổ 9, Thạch Bàn, Long Biên, Hà Nội
I34: Nguyễn Thị Hoa | J34: 0372664026 | K34: Số 16/ 640/ 41 Nguyễn Văn Cừ ,Gia Thụy, Long Biên, Hà Nội
I35: #N/A | J35: #N/A | K35: #N/A
I36: Lò Thị Quỳnh Lan | J36: 0389981982 | K36: Lk26- khu đất đấu giá tổ 11, Phường Thạch Bàn, Quận Long Biên, Hà Nội
I37: Nguyễn Thị Hải Lệ | J37: 0916562655 | K37: Tổ dân phố số 12, Phường Ngọc Lâm, Quận Long Biên, Thành phố Hà Nội
I38: Bùi Thị Hồng Thúy | J38: 0 | K38: Tổ dân phố số 9, Phường Phúc Lợi, Quận Long Biên, Thành phố Hà Nội
I39: Trần Thị Thu | J39: 0972825402 | K39: Tổ dân phố số 3, Phường Cự Khối, Quận Long Biên, Thành phố Hà Nội
I40: Lê Thị Thành | J40: 0961270550 | K40: Tổ 17, Phường Bồ Đề, Quận Long Biên, Thành phố Hà Nội
I41: Đỗ Thị Hương Lan | J41: 0946397747 | K41: Tổ dân phố số 11, Phường Bồ Đề, Quận Long Biên, Thành phố Hà Nội
I42: Nguyễn Thị Hồ Lý | J42: 0988390863 | K42: Tổ dân phố An Lạc, Thị trấn Trâu Quỳ, Huyện Gia Lâm, Thành phố Hà Nội
I43: Lê Thị Duyên | J43: 0986318058 | K43: Thôn 5, Xã Đông Dư, Huyện Gia Lâm, Thành phố Hà Nội
I44: Nguyễn Thị Thu Hà | J44: 0901435688 | K44: Số 5/23 Vũ Xuân Thiều, Phường Phúc Lợi, Quận Long Biên, Thành phố Hà Nội
I45: Nguyễn Thị Huệ | J45: 0978413159 | K45: Tổ 10, Phường Thạch Bàn, Quận Long Biên, Thành phố Hà Nội
I46: Nguyễn Phương Anh | J46: 0948679879 | K46: Phường Sài Đồng, Quận Long Biên, Thành phố Hà Nội
I47: Nguyễn Thị Kỷ | J47: 0389995665 | K47: Tổ dân phố số 38, Phố Bắc Cầu, Phường Ngọc Thụy, Quận Long Biên, Thành phố Hà Nội
I48: Đặng Thị Hồng Vân | J48: 0962768236 | K48: Tổ dân phố số 17, Phường Ngọc Thụy, Quận Long Biên, Thành phố Hà Nội
I49: Nguyễn Thị Ngoan | J49: 0934582291 | K49: Tổ dân phố số 2, Phường Giang Biên, Quận Long Biên, Thành phố Hà Nội
...

Sheet Data_HS t9
A1: Stt | B1: Hovaten | C1: ID_Lop | D1: sinh ngày | E1: giới tính | F1: sdt1 | G1: Bố | H1: SDt2 | I1: Mẹ | J1: sdt 3 | K1: Địa chỉ
A2: 1 | B2: Đinh Nguyên Dương | C2: SV11.1.1 | D2: 01/02/2009 | E2: Nam | F2: 0987218698 | G2: Đinh Quang Sơn | H2: 0968355949 | I2: Nguyễn Thị Quyên | J2: 0987218698 | K2: Tổ dân phố số 36, Phường Ngọc Thụy, Quận Long Biên, Thành phố Hà Nội
A3: 2 | B3: Hoàng Khánh Nam | C3: SV11.1.2 | D3: 03/09/2009 | E3: Nam | F3: 0961227887 | G3: Hoàng Văn Khánh | H3: 0912095104 | I3: Nguyễn Thị Hiền | J3: 0961227887 | K3: Phường Sài Đồng, Quận Long Biên, Thành phố Hà Nội
A4: 3 | B4: Hoàng Minh Quân | C4: SV11.1.3 | D4: 30/09/2009 | E4: Nam | F4: 0943606816 | G4: Hoàng Văn Quyền | H4: 0915830909 | I4: Đặng Quỳnh Trang | J4: 0943606816 | K4: Tổ dân phố số 1, Phường Cự Khối, Quận Long Biên, Thành phố Hà Nội
A5: 4 | B5: Nghiêm Thành Đạt | C5: SV11.1.4 | D5: 28/04/2009 | E5: Nam | F5: 0985477918 | G5: Nghiêm Phú Cường | H5: 0985477918 | I5: Trần Thị Huyền | J5: 0985477918 | K5: Tổ dân phố số 7, Phường Ngọc Thụy, Quận Long Biên, Thành phố Hà Nội
A6: 5 | B6: Nghiêm Xuân Bảo Minh | C6: SV11.1.5 | D6: 12/02/2009 | E6: Nam | F6: 0975375588 | G6: Nghiêm Xuân Khánh | H6: 0366607004 | I6: Lưu Phương Dung | J6: 0975375588 | K6: Phường Việt Hưng, Quận Long Biên, Thành phố Hà Nội
A7: 6 | B7: Nguyễn Đăng Khôi | C7: SV11.1.6 | D7: 14/07/2009 | E7: Nam | F7: 0921916686 | G7: Nguyễn Tiến Mạnh | H7: 0913123399 | I7: Nguyễn Thị Quỳnh Hương | J7: 0921916686 | K7: Tổ dân phố số 14, Phường Việt Hưng, Quận Long Biên, Thành phố Hà Nội
A8: 7 | B8: Nguyễn Gia Khoa | C8: SV11.1.7 | D8: 05/12/2009 | E8: Nam | F8: 0916187589 | G8: Nguyễn Thanh Hùng | H8: 0916187589 | I8: Nguyễn Thị Mai | J8: 0898575223 | K8: Tổ dân phố An Lạc, Thị trấn Trâu Quỳ, Huyện Gia Lâm, Thành phố Hà Nội
A9: 8 | B9: Nguyễn Gia Kỳ | C9: SV11.1.8 | D9: 22/08/2009 | E9: Nam | F9: 0978392117 | G9: Nguyễn Đức Cường | H9: 0915190258 | I9: Chu Thị Mỹ Châu | J9: 0978392117 | K9: Tổ dân phố số 10, Phường Cự Khối, Quận Long Biên, Thành phố Hà Nội
A10: 9 | B10: Nguyễn Khánh Phương | C10: SV11.1.9 | D10: 24/11/2009 | E10: Nữ | F10: 0963284506 | G10: Nguyễn Quốc Đạt | H10: 0963284506 | I10: Nguyễn Thị Tuyết Hạnh | J10: 0989318075 | K10: Tổ dân phố An Đào, Thị trấn Trâu Quỳ, Huyện Gia Lâm, Thành phố Hà Nội
A11: 10 | B11: Nguyễn Phương Thủy | C11: SV11.1.10 | D11: 26/04/2009 | E11: Nữ | F11: 0916558877 | G11: Nguyễn Thế Hưng | H11: 0916558867 | I11: Trần Phương Thảo | J11: 0916558867 | K11: Tổ dân phố số 13, Phường Bồ Đề, Quận Long Biên, Thành phố Hà Nội
A12: 11 | B12: Nguyễn Thu Ngân | C12: SV11.1.11 | D12: 04/01/2009 | E12: Nữ | F12: 0989127588 | G12: Nguyễn Ngọc Thái | H12: 0989127588 | I12: Lê Thị Chi | J12: 0989127588 | K12: Tổ dân phố 10, Phường Phúc Xá, Quận Ba Đình, Thành phố Hà Nội
A13: 13 | B13: Nguyễn Vũ Minh Anh | C13: SV11.1.13 | D13: 13/05/2009 | E13: Nữ | F13: 0982790289 | G13: Nguyễn Minh Mẫn | H13: 0 | I13: Vũ Hồng Giang | J13: 0982790289 | K13: Phường Ngọc Lâm, Quận Long Biên, Thành phố Hà Nội
A14: 15 | B14: Phạm Gia Minh | C14: SV11.1.15 | D14: 14/11/2009 | E14: Nam | F14: 0913132268 | G14: Phạm Anh Đức | H14: 0913132268 | I14: Nguyễn Thị Loan | J14: 0368947535 | K14: Tổ 5, Phường Vĩnh Hưng, Quận Hoàng Mai, Thành phố Hà Nội
A15: 17 | B15: Trần Đức Anh | C15: SV11.1.17 | D15: 09/01/2009 | E15: Nam | F15: 0915225659 | G15: Trần Thanh Hùng | H15: 0912317676 | I15: Nguyễn Thị Bích Phương | J15: 0915225659 | K15: Phường Đức Giang, Quận Long Biên, Thành phố Hà Nội
A16: 18 | B16: Trần Khôi Nguyên | C16: SV11.1.18 | D16: 07/10/2009 | E16: Nam | F16: 0976596686 | G16: Trần Tuấn Anh | H16: 0978333878 | I16: Nguyễn Thị Hải | J16: 0976596686 | K16: Tổ dân phố số 2, Phường Long Biên, Quận Long Biên, Thành phố Hà Nội
A17: 19 | B17: Vũ Thị Thanh Phương | C17: SV11.1.19 | D17: 25/02/2009 | E17: Nữ | F17: 0898272016 | G17: Vũ Văn Nguyên | H17: 0898272016 | I17: Lê Thu Hương | J17: 0972762509 | K17: Tòa S1-01-02-03-05-06-07-08-09, Vinhome Ocean Park, Xã Đa Tốn, Huyện Gia Lâm, Thành phố Hà Nội
A18: 21 | B18: Lê Ngọc Như Anh | C18: SV11.1.21 | D18: 26/04/2009 | E18: Nữ | F18: 0862793108 | G18: Lê Tiến Dũng | H18: 0986130707 | I18: Vũ Thị Thu Hương | J18: 0862793108 | K18: Tổ dân phố số 4, Xã Đặng Xá, Huyện Gia Lâm, Thành phố Hà Nội
A19: 1 | B19: Hoàng Khánh Linh Anh | C19: SV11.2.1 | D19: 40098 | E19: Nữ | F19: 0923832012 | G19: Hoàng Tâm | H19: 0913313131 | I19: Nguyễn Thị Thanh Thủy | J19: 0946228884 | K19: Tổ 9 - Thạch Bàn - Long Biên- Hà Nội
A20: 2 | B20: Khổng Quốc An | C20: SV11.2.2 | D20: 40060 | E20: Nam | F20: 0582016768 | G20: KHỔNG ĐÌNH HƯNG | H20: 0913564546 | I20: ĐỖ THỊ HOA | J20: 0947246556 | K20: 29 ngõ 71 tổ 4 thạch bàn long biên hà nôi
A21: 3 | B21: Lê Mạc Thuỳ Trinh | C21: SV11.2.3 | D21: #N/A | E21: #N/A | F21: #N/A | G21: #N/A | H21: #N/A | I21: #N/A | J21: #N/A | K21: #N/A
A22: 4 | B22: Lương Đức Huy | C22: SV11.2.4 | D22: 40135 | E22: Nam | F22: 0833171519 | G22: Lương Thanh Hiếu | H22: 0912445906 | I22: Vũ Kim Ngân | J22: 0947011800 | K22: Thạch Bàn, Long Biên, Hà Nội
A23: 5 | B23: Lương Ngọc Vy | C23: SV11.2.5 | D23: 39937 | E23: Nữ | F23: 0869702665 | G23: Lương Ngọc Lân | H23: 0975278268 | I23: Vũ Hoàng Anh | J23: 0977883636 | K23: Số 41A/62 Hoàng Như Tiếp, Bồ Đề, Long Biên, Hà Nội
A24: 6 | B24: Lưu Tường Mai Phương | C24: SV11.2.6 | D24: #N/A | E24: #N/A | F24: #N/A | G24: #N/A | H24: #N/A | I24: #N/A | J24: #N/A | K24: #N/A
A25: 7 | B25: Nguyễn Duy Dũng | C25: SV11.2.7 | D25: 39856 | E25: Nam | F25: 0879993643 | G25: Nguyễn Duy Giang | H25: 0888702868 | I25: Nguyễn Thị Trang | J25: 0946820088 | K25: Số nhà 6c, ngõ 39, phố Ngọc Trì, Thạch Bàn, Long Biên, Hà Nội
A26: 8 | B26: Nguyễn Hải Nam | C26: SV11.2.8 | D26: 40028 | E26: Nam | F26: 0338143817 | G26: Nguyễn Nam Hải | H26: 0988484285 | I26: Nguyễn Phương Thúy | J26: 0963999386 | K26: Tổ dân phố An Lạc, TT Trâu Quỳ, Gia Lâm, Hà Nội
A27: 9 | B27: Nguyễn Hữu Nam | C27: SV11.2.9 | D27: 40072 | E27: Nam | F27: 0337635606 | G27: Nguyễn Hữu Phương | H27: 0968501111 | I27: Lò Thị Quỳnh Lan | J27: 0389981982 | K27: Lk26- khu đất đấu giá tổ 11, Phường Thạch Bàn, Quận Long Biên, Hà Nội
A28: 10 | B28: Nguyễn Khánh An | C28: SV11.2.10 | D28: #N/A | E28: #N/A | F28: #N/A | G28: #N/A | H28: #N/A | I28: #N/A | J28: #N/A | K28: #N/A
A29: 11 | B29: Nguyễn Minh Phúc | C29: SV11.2.11 | D29: 40081 | E29: Nam | F29: 0393486494 | G29: Nguyễn Thanh Sơn | H29: 0936738067 | I29: Lê Thị Lưu | J29: 0389252265 | K29: An Lạc. Trâu Quỳ, Gia Lân, Hà Nội
A30: 12 | B30: Nguyễn Thị Minh Hằng | C30: SV11.2.12 | D30: 40103 | E30: Nữ | F30: 0396399209 | G30: Nguyễn Thế Thành | H30: 0366823044 | I30: Nguyễn Thị Hoa | J30: 0372664026 | K30: Số 16/ 640/ 41 Nguyễn Văn Cừ ,Gia Thụy, Long Biên, Hà Nội
A31: 14 | B31: Phạm Hiển Long | C31: SV11.2.14 | D31: #N/A | E31: #N/A | F31: #N/A | G31: #N/A | H31: #N/A | I31: #N/A | J31: #N/A | K31: #N/A
A32: 15 | B32: Phạm Thu Giang | C32: SV11.2.15 | D32: 39992 | E32: Nữ | F32: 0364200761 | G32: Phạm Văn Hậu | H32: 0988524552 | I32: Dương Thị Thu Hương | J32: 0986317405 | K32: Số 2, ngách 565/45, đường Bát Khối, tổ 10, Cự Khối, Long Biên, Hà Nội
A33: 16 | B33: Phan Quốc Anh | C33: SV11.2.16 | D33: 40078 | E33: Nam | F33: 0795088009 | G33: Phan Trung Thực | H33: 0912012209 | I33: Phạm Thị Thúy Hằng | J33: 0935115222 | K33: Chung cư quân đội ct1 thạch bàn long biên hà nội
A34: 17 | B34: Trần Đình Dũng | C34: SV11.2.17 | D34: 39832 | E34: Nam | F34: 081 558 2686 | G34: Trần Đình Kiên | H34: 0979 98 1289 | I34: Lương Thị Anh | J34: 091 6622 590 | K34: Số 9 , Hẻm 68/79/94 Nguyễn Văn Linh , Tổ 15 , Thạch Bàn , Long Biên ,Hà Nội
A35: 18 | B35: Trần Quang Hưng | C35: SV11.2.18 | D35: 39839 | E35: Nam | F35: 0335163695 | G35: TRẦN TUẤN QUANG | H35: 0914387952 | I35: BÙI THỊ THANH THẢO | J35: 0902101922 | K35: Tổ 21, phường Bồ Đề, Long Biên, Hà Nội
A36: 19 | B36: Trần Trọng Dũng | C36: SV11.2.19 | D36: 39910 | E36: Nam | F36: 0354569962 | G36: Trần Văn Tĩnh | H36: 0985103438 | I36: Bùi Thị Thắm | J36: 0354569962 | K36: P711, CC CT2A, Tổ 17, Thạch Bàn, Long Biên, Hà Nội
A37: 20 | B37: Trương Ngọc Vy | C37: SV11.2.20 | D37: 40024 | E37: Nữ | F37: 0962740810 | G37: TRƯƠNG HỒNG QUYẾT | H37: 0976178486 | I37: NGÔ THỊ THANH HƯƠNG | J37: 0397661482 | K37: Tổ 10, Phường Thạch Bàn, Quận Long Biên, TP Hà Nội
A38: 26 | B38: Vũ Minh Đức | C38: SV11.2.26 | D38: 0 | E38: 0 | F38: 0 | G38: 0 | H38: 0 | I38: 0 | J38: 0 | K38: 0
A39: 1 | B39: Đặng Phú Thái | C39: SV11.3.1 | D39: 26/09/2009 | E39: Nam | F39: 0389995665 | G39: Đặng Xuân Hải | H39: 0982998266 | I39: Nguyễn Thị Kỷ | J39: 0389995665 | K39: Tổ dân phố số 38, Phố Bắc Cầu, Phường Ngọc Thụy, Quận Long Biên, Thành phố Hà Nội
A40: 2 | B40: Đặng Quỳnh Chi | C40: SV11.3.2 | D40: 01/09/2009 | E40: Nữ | F40: 0912832779 | G40: Đặng Văn Vinh | H40: 0912832779 | I40: Bùi Thị Hồng Thúy | J40: 0 | K40: Tổ dân phố số 9, Phường Phúc Lợi, Quận Long Biên, Thành phố Hà Nội
...
